<robot name="open_abcrover">
    <link name="base_footprint"/>

    <joint name="base_joint" type="fixed">
        <origin xyz="0 0 0.1332"/>
        <parent link="base_footprint"/>
        <child link="base_frame"/>
    </joint>

    <link name="base_frame">
        <visual>
            <geometry>
                <mesh filename="package://open_abcrover/description/meshes/base_frame_indoor.stl"/>
            </geometry>
        </visual>
        <collision>
            <geometry>
                <box size="0.293 0.337 0.241"/>
            </geometry>
        </collision>
        <inertial>
            <mass value="3.258"/>
            <inertia ixx="0.026" ixy="-1.421e-4" ixz="1.997e-5" iyy="0.02" iyz="0.005" izz="0.032"/>
        </inertial>
    </link>

    <joint name="base_to_leftwheel" type="continuous">
        <origin xyz="0.1235 -0.0488 -0.057"/>
        <axis xyz="1 0 0"/>
        <parent link="base_frame"/>
        <child link="left_wheel"/>
    </joint>

    <link name="left_wheel">
        <visual>
            <geometry>
                <mesh filename="package://open_abcrover/description/meshes/wheel_left.stl"/>
            </geometry>
        </visual>
        <collision>
            <geometry>
                <box size="0.045 0.152 0.152"/>
            </geometry>
        </collision>
        <inertial>
            <mass value="0.216"/>
            <inertia ixx="7.441e-4" ixy="-1.139e-8" ixz="5.172e-8" iyy="5.313e-4" iyz="4.204e-8" izz="5.311e-04"/>
        </inertial>
    </link>

    <joint name="base_to_rightwheel" type="continuous">
        <origin xyz="-0.1235 -0.0488 -0.057"/>
        <axis xyz="1 0 0"/>
        <parent link="base_frame"/>
        <child link="right_wheel"/>
    </joint>

    <link name="right_wheel">
        <visual>
            <geometry>
                <mesh filename="package://open_abcrover/description/meshes/wheel_right.stl"/>
            </geometry>
        </visual>
        <collision>
            <geometry>
                <box size="0.045 0.152 0.152"/>
            </geometry>
        </collision>
        <inertial>
            <mass value="0.216"/>
            <inertia ixx="7.441e-4" ixy="-1.139e-8" ixz="-5.172e-8" iyy="5.313e-4" iyz="-4.204e-8" izz="5.311e-04"/>
        </inertial>
    </link>
</robot>