<robot name="open_abcrover">
    <link name="base_footprint"/>

    <joint name="base_joint" type="fixed">
        <origin xyz="0 0 0.1332"/>
        <parent link="base_footprint"/>
        <child link="base_frame"/>
    </joint>

    <link name="base_frame">
        <visual>
            <geometry>
                <mesh filename="package://open_abcrover/description/meshes/base_frame_indoor.stl"/>
            </geometry>
        </visual>
        <collision>
            <geometry>
                <box size="0.293 0.337 0.241"/>
            </geometry>
        </collision>
        <inertial>
            <mass value="3.258"/>
            <inertia ixx="0.026" ixy="-0.0001421" ixz="0.00001997" iyy="0.02" iyz="0.005" izz="0.032"/>
        </inertial>
    </link>

    <joint name="base_to_leftwheel" type="continuous">
        <origin xyz="0.1235 -0.0488 -0.057"/>
        <axis xyz="1 0 0"/>
        <parent link="base_frame"/>
        <child link="left_wheel"/>
    </joint>

    <link name="left_wheel">
        <visual>
            <geometry>
                <mesh filename="package://open_abcrover/description/meshes/wheel_left.stl"/>
            </geometry>
        </visual>
        <collision>
            <geometry>
                <box size="0.045 0.152 0.152"/>
            </geometry>
        </collision>
        <inertial>
            <mass value="0.216"/>
            <inertia ixx="0.0007441" ixy="-0.00000001139" ixz="0.00000005172" iyy="0.0005313" iyz="0.00000004204" izz="0.0005311"/>
        </inertial>
    </link>

    <joint name="base_to_rightwheel" type="continuous">
        <origin xyz="-0.1235 -0.0488 -0.057"/>
        <axis xyz="1 0 0"/>
        <parent link="base_frame"/>
        <child link="right_wheel"/>
    </joint>

    <link name="right_wheel">
        <visual>
            <geometry>
                <mesh filename="package://open_abcrover/description/meshes/wheel_right.stl"/>
            </geometry>
        </visual>
        <collision>
            <geometry>
                <box size="0.045 0.152 0.152"/>
            </geometry>
        </collision>
        <inertial>
            <mass value="0.216"/>
            <inertia ixx="0.0007441" ixy="-0.00000001139" ixz="-0.00000005172" iyy="0.0005313" iyz="-0.00000004204" izz="0.0005311"/>
        </inertial>
    </link>
</robot>